** TestPreamble **

Question about proj1/main.py: How does proj1/main.py handle errors?

Error generating response: HTTPConnectionPool(host='localhost', port=11434): Max retries exceeded with url: /api/generate (Caused by NewConnectionError('<urllib3.connection.HTTPConnection object at 0x7f5e76f3e710>: Failed to establish a new connection: [Errno 111] Connection refused'))

This answer includes code analysis and business logic explanations based on the codebase.
